<?xml version="1.0"?>
<robot xmlns:xacro="http://www.ros.org/wiki/xacro">

  <!-- Macro for the complete lunar robot -->
  <xacro:macro name="lunar_robot_core" params="chassis_length chassis_width chassis_height chassis_mass wheel_radius wheel_width wheel_mass wheel_separation config">

    <!-- Base footprint (for navigation) -->
    <link name="base_footprint"/>

    <joint name="base_joint" type="fixed">
      <parent link="base_footprint"/>
      <child link="base_link"/>
      <origin xyz="0.0 0.0 ${wheel_radius}" rpy="0 0 0"/>
    </joint>

    <!-- Main chassis -->
    <link name="base_link">
      <visual>
        <origin xyz="0 0 0" rpy="0 0 0"/>
        <geometry>
          <box size="${chassis_length} ${chassis_width} ${chassis_height}"/>
        </geometry>
        <material name="silver"/>
      </visual>
      
      <collision>
        <origin xyz="0 0 0" rpy="0 0 0"/>
        <geometry>
          <box size="${chassis_length} ${chassis_width} ${chassis_height}"/>
        </geometry>
      </collision>
      
      <inertial>
        <origin xyz="0 0 0" rpy="0 0 0"/>
        <mass value="${chassis_mass}"/>
        <inertia ixx="${(1/12) * chassis_mass * (chassis_width*chassis_width + chassis_height*chassis_height)}" 
                 ixy="0" ixz="0"
                 iyy="${(1/12) * chassis_mass * (chassis_length*chassis_length + chassis_height*chassis_height)}" 
                 iyz="0"
                 izz="${(1/12) * chassis_mass * (chassis_length*chassis_length + chassis_width*chassis_width)}"/>
      </inertial>
    </link>

    <!-- Wheels using positions from config -->
    <xacro:property name="wheel_positions" value="${config['wheel_positions']}"/>
    
    <!-- Front Left Wheel -->
    <xacro:wheel_assembly
      wheel_name="front_left"
      parent_link="base_link"
      x_pos="${wheel_positions['front_left']['x']}"
      y_pos="${wheel_positions['front_left']['y']}"
      z_pos="${wheel_positions['front_left']['z']}"
      wheel_radius="${wheel_radius}"
      wheel_width="${wheel_width}"
      wheel_mass="${wheel_mass}"/>

    <!-- Front Right Wheel -->
    <xacro:wheel_assembly
      wheel_name="front_right"
      parent_link="base_link"
      x_pos="${wheel_positions['front_right']['x']}"
      y_pos="${wheel_positions['front_right']['y']}"
      z_pos="${wheel_positions['front_right']['z']}"
      wheel_radius="${wheel_radius}"
      wheel_width="${wheel_width}"
      wheel_mass="${wheel_mass}"/>

    <!-- Rear Left Wheel -->
    <xacro:wheel_assembly
      wheel_name="rear_left"
      parent_link="base_link"
      x_pos="${wheel_positions['rear_left']['x']}"
      y_pos="${wheel_positions['rear_left']['y']}"
      z_pos="${wheel_positions['rear_left']['z']}"
      wheel_radius="${wheel_radius}"
      wheel_width="${wheel_width}"
      wheel_mass="${wheel_mass}"/>

    <!-- Rear Right Wheel -->
    <xacro:wheel_assembly
      wheel_name="rear_right"
      parent_link="base_link"
      x_pos="${wheel_positions['rear_right']['x']}"
      y_pos="${wheel_positions['rear_right']['y']}"
      z_pos="${wheel_positions['rear_right']['z']}"
      wheel_radius="${wheel_radius}"
      wheel_width="${wheel_width}"
      wheel_mass="${wheel_mass}"/>

    <!-- ROS2 Control interface -->
   <!--
      <ros2_control name="lunar_robot_control" type="system">
      <hardware>
       
        <plugin>gz_ros2_control/GazeboSimSystem</plugin>
      </hardware>
      
      
      <joint name="front_left_wheel_joint">
        <command_interface name="velocity">
          <param name="min">-10</param>
          <param name="max">10</param>
        </command_interface>
        <state_interface name="velocity"/>
        <state_interface name="position"/>
      </joint>
      
      <joint name="rear_left_wheel_joint">
        <command_interface name="velocity">
          <param name="min">-10</param>
          <param name="max">10</param>
        </command_interface>
        <state_interface name="velocity"/>
        <state_interface name="position"/>
      </joint>

      <joint name="front_right_wheel_joint">
        <command_interface name="velocity">
          <param name="min">-10</param>
          <param name="max">10</param>
        </command_interface>
        <state_interface name="velocity"/>
        <state_interface name="position"/>
      </joint>
      
      <joint name="rear_right_wheel_joint">
        <command_interface name="velocity">
          <param name="min">-10</param>
          <param name="max">10</param>
        </command_interface>
        <state_interface name="velocity"/>
        <state_interface name="position"/>
      </joint>
    </ros2_control>

    
    <gazebo>
      <plugin filename="gz_ros2_control-system" name="gz_ros2_control::GazeboSimROS2ControlPlugin">
        <parameters>$(find lunar_robot_description)/config/robot_control.yaml</parameters>
      </plugin>
    </gazebo>
    -->
  </xacro:macro>

  <!-- Wheel assembly macro -->
  <xacro:macro name="wheel_assembly" params="wheel_name parent_link x_pos y_pos z_pos wheel_radius wheel_width wheel_mass">
    
    <joint name="${wheel_name}_wheel_joint" type="continuous">
      <parent link="${parent_link}"/>
      <child link="${wheel_name}_wheel"/>
      <origin xyz="${x_pos} ${y_pos} ${z_pos}" rpy="-1.5708 0 0"/>
      <axis xyz="0 0 1"/>
    </joint>

    <link name="${wheel_name}_wheel">
      <visual>
        <origin xyz="0 0 0" rpy="0 0 0"/>
        <geometry>
          <cylinder radius="${wheel_radius}" length="${wheel_width}"/>
        </geometry>
        <material name="black"/>
      </visual>
      
      <collision>
        <origin xyz="0 0 0" rpy="0 0 0"/>
        <geometry>
          <cylinder radius="${wheel_radius}" length="${wheel_width}"/>
        </geometry>
      </collision>
      
      <inertial>
        <origin xyz="0 0 0" rpy="0 0 0"/>
        <mass value="${wheel_mass}"/>
        <inertia ixx="${(1/12) * wheel_mass * (3*wheel_radius*wheel_radius + wheel_width*wheel_width)}" 
                 ixy="0" ixz="0"
                 iyy="${(1/12) * wheel_mass * (3*wheel_radius*wheel_radius + wheel_width*wheel_width)}" 
                 iyz="0"
                 izz="${0.5 * wheel_mass * wheel_radius * wheel_radius}"/>
      </inertial>
    </link>

    <!-- Gazebo friction and material properties -->
    <gazebo reference="${wheel_name}_wheel">
      <material>Gazebo/DarkGrey</material>
      <mu1>1.0</mu1>
      <mu2>1.0</mu2>
      <kp>500000.0</kp>
      <kd>10.0</kd>
      <minDepth>0.001</minDepth>
      <maxVel>0.1</maxVel>
    </gazebo>

  </xacro:macro>

</robot>
